#VRML_SIM R2021a utf8
WorldInfo {
  defaultDamping Damping {
  }
  coordinateSystem "NUE"
}
Viewpoint {
  fieldOfView 0.7
  orientation -0.04240750583487445 0.8689773554949334 0.49303139766742765 3.2821713284538427
  position -2.059948716536101 16.818315212622004 -10.343206057184684
}
DirectionalLight {
  direction 0 -5 -10
  intensity 0.5
}
DirectionalLight {
  direction 10 -5 -5
  intensity 0.1
}
DirectionalLight {
  direction -11 -5 -5
  intensity 0.1
}
DirectionalLight {
  direction 0 -5 15
  intensity 0.1
}
RectangleArena {
  translation -0.02 0 0.23
  floorSize 7 6
}
DEF RobotLightC1 Robot {
  translation 2.1 0.04 -2.44
  children [
    Receiver {
      name "rec2"
      channel 2
    }
    Receiver {
      name "rec3"
      channel 3
    }
    Receiver {
      name "rec4"
      channel 4
    }
    Receiver {
      name "rec5"
      channel 5
    }
    Receiver {
      name "rec6"
      channel 6
    }
    Receiver {
      name "rec7"
      channel 7
    }
    Receiver {
      name "rec8"
      channel 8
    }
    Receiver {
      name "rec9"
      channel 9
    }
    Receiver {
      name "rec1"
      channel 10
    }
    Receiver {
      name "rec10"
      channel 11
    }
    Receiver {
      name "rec11"
      channel 12
    }
    Receiver {
      name "rec12"
      channel 13
    }
    Receiver {
      name "rec13"
      channel 14
    }
    Receiver {
      name "rec14"
      channel 15
    }
    Receiver {
      name "rec15"
      channel 14
    }
    Receiver {
      translation 1.75 0 0
      name "rec16"
      channel 17
    }
    Receiver {
      translation 1.75 0 0
      name "rec17"
      channel 18
    }
    Receiver {
      translation 1.75 0 0
      name "rec18"
      channel 19
    }
    Receiver {
      translation 1.75 0 0
      name "rec19"
      channel 20
    }
    Receiver {
      translation 1.75 0 0
      name "rec20"
      channel 21
    }
    Receiver {
      translation 1.75 0 0
      name "rec21"
      channel 22
    }
    Receiver {
      translation 1.75 0 0
      name "rec22"
      channel 23
    }
    Receiver {
      translation 1.75 0 0
      name "rec23"
      channel 24
    }
    Receiver {
      translation 1.75 0 0
      name "rec24"
      channel 25
    }
    Emitter {
      name "trans"
      range 1
      maxRange 1
      channel 1
    }
    Compass {
      name "com"
      yAxis FALSE
    }
    LightSensor {
      translation -0.02 0.04 0.02
      rotation 0 1 0 -2.35619
      children [
        DEF ls Shape {
          appearance Appearance {
            material Material {
              diffuseColor 1 1 0
            }
          }
          geometry Box {
            size 0.01 0.04 0.01
          }
        }
      ]
      name "ls1"
      boundingObject USE ls
      physics Physics {
      }
      occlusion TRUE
    }
    LightSensor {
      translation -0.02 0.04 -0.02
      rotation 0 1 0 -3.92699
      children [
        DEF ls Shape {
          appearance Appearance {
            material Material {
              diffuseColor 1 1 0
            }
          }
          geometry Box {
            size 0.01 0.04 0.01
          }
        }
      ]
      name "ls2"
      boundingObject USE ls
      physics Physics {
      }
      occlusion TRUE
    }
    LightSensor {
      translation 0.02 0.04 -0.02
      rotation 0 1 0 0.785398
      children [
        DEF ls Shape {
          appearance Appearance {
            material Material {
              diffuseColor 1 1 0
            }
          }
          geometry Box {
            size 0.01 0.04 0.01
          }
        }
      ]
      name "ls3"
      boundingObject USE ls
      physics Physics {
      }
      occlusion TRUE
    }
    LightSensor {
      translation 0.02 0.04 0.02
      rotation 0 1 0 -0.785398
      children [
        DEF ls Shape {
          appearance Appearance {
            material Material {
              diffuseColor 1 1 0
            }
          }
          geometry Box {
            size 0.01 0.04 0.01
          }
        }
      ]
      name "ls4"
      boundingObject USE ls
      physics Physics {
      }
      occlusion TRUE
    }
    DistanceSensor {
      translation 0 0 0.1
      rotation 0 1 0 -1.5708
      children [
        DEF DS Shape {
          appearance Appearance {
            material Material {
            }
          }
          geometry Box {
            size 0.01 0.01 0.01
          }
        }
      ]
      name "ds"
      boundingObject USE DS
      physics Physics {
      }
      lookupTable [
        0 0 0
        0.2 400 0
        0.5 1000 0
      ]
    }
    HingeJoint {
      jointParameters HingeJointParameters {
        anchor -0.06 0 -0.05
      }
      device [
        DEF wheel4 RotationalMotor {
          name "wheel4"
          acceleration 1
        }
      ]
      endPoint DEF WHEEL4 Solid {
        translation -0.05999991814307717 -9.632061444724494e-06 -0.05000362374001422
        rotation 0.03312248218235521 -0.03304576865397035 0.9989048394857981 1.571866762233069
        children [
          DEF WHEEL Shape {
            appearance Appearance {
              material Material {
                diffuseColor 0 0 1
              }
            }
            geometry Cylinder {
              height 0.02
              radius 0.04
            }
          }
        ]
        name "wheel4"
        boundingObject USE WHEEL
        physics DEF WHEEL_PH Physics {
        }
      }
    }
    HingeJoint {
      jointParameters HingeJointParameters {
        anchor 0.06 0 -0.05
      }
      device [
        DEF wheel3 RotationalMotor {
          name "wheel3"
          acceleration 1
        }
      ]
      endPoint DEF WHEEL3 Solid {
        translation 0.060000176302764274 -1.3570422243021472e-05 -0.04999976121740486
        rotation 0.033052858076168264 -0.03297527418051867 0.9989094753108093 1.5718690848001053
        children [
          DEF WHEEL Shape {
            appearance Appearance {
              material Material {
                diffuseColor 0 0 1
              }
            }
            geometry Cylinder {
              height 0.02
              radius 0.04
            }
          }
        ]
        name "wheel3"
        boundingObject USE WHEEL
        physics USE WHEEL_PH
      }
    }
    HingeJoint {
      jointParameters HingeJointParameters {
        anchor -0.06 0 0.05
      }
      device [
        DEF wheel2 RotationalMotor {
          name "wheel2"
          acceleration 1
        }
      ]
      endPoint DEF WHEEL2 Solid {
        translation -0.060002157958187 -8.7540512070535e-06 0.049996310781291034
        rotation 0.033122390039492314 -0.03304586831487273 0.9989048392441533 1.5718664036508943
        children [
          DEF WHEEL Shape {
            appearance Appearance {
              material Material {
                diffuseColor 0 0 1
              }
            }
            geometry Cylinder {
              height 0.02
              radius 0.04
            }
          }
        ]
        name "wheel2"
        boundingObject USE WHEEL
        physics DEF WHEEL_PH Physics {
        }
      }
    }
    DEF BODY Shape {
      appearance Appearance {
        material Material {
          diffuseColor 1 0 0
        }
      }
      geometry Box {
        size 0.1 0.05 0.2
      }
    }
    HingeJoint {
      jointParameters HingeJointParameters {
        anchor 0.06 0 0.05
      }
      device [
        DEF wheel1 RotationalMotor {
          name "wheel1"
        }
      ]
      endPoint DEF WHEEL1 Solid {
        translation 0.06000190297626937 6.2227360664119e-06 0.049995882054905696
        rotation -0.04651496824615402 0.046637305478202655 -0.9978283015964179 4.710224110905362
        children [
          DEF WHEEL Shape {
            appearance Appearance {
              material Material {
                diffuseColor 0 0 1
              }
            }
            geometry Cylinder {
              height 0.02
              radius 0.04
            }
          }
        ]
        name "wheel1"
        boundingObject USE WHEEL
        physics USE WHEEL_PH
      }
    }
  ]
  name "RL"
  boundingObject USE BODY
  physics Physics {
  }
  controller "RobotLightP_4_robota"
}
DEF RobotLightC2 Robot {
  translation -1.37 0.04 -2.5
  children [
    Receiver {
      name "rec1"
      channel 1
    }
    Receiver {
      name "rec3"
      channel 3
    }
    Receiver {
      name "rec4"
      channel 4
    }
    Receiver {
      name "rec5"
      channel 5
    }
    Receiver {
      name "rec6"
      channel 6
    }
    Receiver {
      name "rec7"
      channel 7
    }
    Receiver {
      name "rec8"
      channel 8
    }
    Receiver {
      name "rec9"
      channel 9
    }
    Receiver {
      name "rec2"
      channel 10
    }
    Receiver {
      name "rec10"
      channel 11
    }
    Receiver {
      name "rec11"
      channel 12
    }
    Receiver {
      name "rec12"
      channel 13
    }
    Receiver {
      name "rec13"
      channel 14
    }
    Receiver {
      name "rec14"
      channel 15
    }
    Receiver {
      name "rec15"
      channel 14
    }
    Receiver {
      translation 1.75 0 0
      name "rec16"
      channel 17
    }
    Receiver {
      translation 1.75 0 0
      name "rec17"
      channel 18
    }
    Receiver {
      translation 1.75 0 0
      name "rec18"
      channel 19
    }
    Receiver {
      translation 1.75 0 0
      name "rec19"
      channel 20
    }
    Receiver {
      translation 1.75 0 0
      name "rec20"
      channel 21
    }
    Receiver {
      translation 1.75 0 0
      name "rec21"
      channel 22
    }
    Receiver {
      translation 1.75 0 0
      name "rec22"
      channel 23
    }
    Receiver {
      translation 1.75 0 0
      name "rec23"
      channel 24
    }
    Receiver {
      translation 1.75 0 0
      name "rec24"
      channel 25
    }
    Emitter {
      name "trans"
      range 1
      maxRange 1
      channel 2
    }
    Compass {
      name "com"
      yAxis FALSE
    }
    LightSensor {
      translation -0.02 0.04 0.02
      rotation 0 1 0 -2.35619
      children [
        DEF ls Shape {
          appearance Appearance {
            material Material {
              diffuseColor 1 1 0
            }
          }
          geometry Box {
            size 0.01 0.04 0.01
          }
        }
      ]
      name "ls1"
      boundingObject USE ls
      physics Physics {
      }
      occlusion TRUE
    }
    LightSensor {
      translation -0.02 0.04 -0.02
      rotation 0 1 0 -3.92699
      children [
        DEF ls Shape {
          appearance Appearance {
            material Material {
              diffuseColor 1 1 0
            }
          }
          geometry Box {
            size 0.01 0.04 0.01
          }
        }
      ]
      name "ls2"
      boundingObject USE ls
      physics Physics {
      }
      occlusion TRUE
    }
    LightSensor {
      translation 0.02 0.04 -0.02
      rotation 0 1 0 0.785398
      children [
        DEF ls Shape {
          appearance Appearance {
            material Material {
              diffuseColor 1 1 0
            }
          }
          geometry Box {
            size 0.01 0.04 0.01
          }
        }
      ]
      name "ls3"
      boundingObject USE ls
      physics Physics {
      }
      occlusion TRUE
    }
    LightSensor {
      translation 0.02 0.04 0.02
      rotation 0 1 0 -0.785398
      children [
        DEF ls Shape {
          appearance Appearance {
            material Material {
              diffuseColor 1 1 0
            }
          }
          geometry Box {
            size 0.01 0.04 0.01
          }
        }
      ]
      name "ls4"
      boundingObject USE ls
      physics Physics {
      }
      occlusion TRUE
    }
    DistanceSensor {
      translation 0 0 0.1
      rotation 0 1 0 -1.5708
      children [
        DEF DS Shape {
          appearance Appearance {
            material Material {
            }
          }
          geometry Box {
            size 0.01 0.01 0.01
          }
        }
      ]
      name "ds"
      boundingObject USE DS
      physics Physics {
      }
      lookupTable [
        0 0 0
        0.2 400 0
        0.5 1000 0
      ]
    }
    HingeJoint {
      jointParameters HingeJointParameters {
        anchor -0.06 0 -0.05
      }
      device [
        DEF wheel4 RotationalMotor {
          name "wheel4"
          acceleration 1
        }
      ]
      endPoint DEF WHEEL4 Solid {
        translation -0.05999991814307717 -9.632061444724494e-06 -0.05000362374001422
        rotation 0.03312248218235521 -0.03304576865397035 0.9989048394857981 1.571866762233069
        children [
          DEF WHEEL Shape {
            appearance Appearance {
              material Material {
                diffuseColor 0 0 1
              }
            }
            geometry Cylinder {
              height 0.02
              radius 0.04
            }
          }
        ]
        name "wheel4"
        boundingObject USE WHEEL
        physics DEF WHEEL_PH Physics {
        }
      }
    }
    HingeJoint {
      jointParameters HingeJointParameters {
        anchor 0.06 0 -0.05
      }
      device [
        DEF wheel3 RotationalMotor {
          name "wheel3"
          acceleration 1
        }
      ]
      endPoint DEF WHEEL3 Solid {
        translation 0.060000176302764274 -1.3570422243021472e-05 -0.04999976121740486
        rotation 0.033052858076168264 -0.03297527418051867 0.9989094753108093 1.5718690848001053
        children [
          DEF WHEEL Shape {
            appearance Appearance {
              material Material {
                diffuseColor 0 0 1
              }
            }
            geometry Cylinder {
              height 0.02
              radius 0.04
            }
          }
        ]
        name "wheel3"
        boundingObject USE WHEEL
        physics USE WHEEL_PH
      }
    }
    HingeJoint {
      jointParameters HingeJointParameters {
        anchor -0.06 0 0.05
      }
      device [
        DEF wheel2 RotationalMotor {
          name "wheel2"
          acceleration 1
        }
      ]
      endPoint DEF WHEEL2 Solid {
        translation -0.060002157958187 -8.7540512070535e-06 0.049996310781291034
        rotation 0.033122390039492314 -0.03304586831487273 0.9989048392441533 1.5718664036508943
        children [
          DEF WHEEL Shape {
            appearance Appearance {
              material Material {
                diffuseColor 0 0 1
              }
            }
            geometry Cylinder {
              height 0.02
              radius 0.04
            }
          }
        ]
        name "wheel2"
        boundingObject USE WHEEL
        physics DEF WHEEL_PH Physics {
        }
      }
    }
    DEF BODY Shape {
      appearance Appearance {
        material Material {
          diffuseColor 1 0 0
        }
      }
      geometry Box {
        size 0.1 0.05 0.2
      }
    }
    HingeJoint {
      jointParameters HingeJointParameters {
        anchor 0.06 0 0.05
      }
      device [
        DEF wheel1 RotationalMotor {
          name "wheel1"
        }
      ]
      endPoint DEF WHEEL1 Solid {
        translation 0.06000190297626937 6.2227360664119e-06 0.049995882054905696
        rotation -0.04651496824615402 0.046637305478202655 -0.9978283015964179 4.710224110905362
        children [
          DEF WHEEL Shape {
            appearance Appearance {
              material Material {
                diffuseColor 0 0 1
              }
            }
            geometry Cylinder {
              height 0.02
              radius 0.04
            }
          }
        ]
        name "wheel1"
        boundingObject USE WHEEL
        physics USE WHEEL_PH
      }
    }
  ]
  name "RL(1)"
  boundingObject USE BODY
  physics Physics {
  }
  controller "RobotLightP_4_robota"
}
DEF RobotLightC3 Robot {
  translation -0.86 0.04 -2.51
  children [
    Receiver {
      name "rec1"
      channel 1
    }
    Receiver {
      name "rec2"
      channel 2
    }
    Receiver {
      name "rec4"
      channel 4
    }
    Receiver {
      name "rec5"
      channel 5
    }
    Receiver {
      name "rec6"
      channel 6
    }
    Receiver {
      name "rec7"
      channel 7
    }
    Receiver {
      name "rec8"
      channel 8
    }
    Receiver {
      name "rec9"
      channel 9
    }
    Receiver {
      name "rec3"
      channel 10
    }
    Receiver {
      name "rec10"
      channel 11
    }
    Receiver {
      name "rec11"
      channel 12
    }
    Receiver {
      name "rec12"
      channel 13
    }
    Receiver {
      name "rec13"
      channel 14
    }
    Receiver {
      name "rec14"
      channel 15
    }
    Receiver {
      name "rec15"
      channel 14
    }
    Receiver {
      translation 1.75 0 0
      name "rec16"
      channel 17
    }
    Receiver {
      translation 1.75 0 0
      name "rec17"
      channel 18
    }
    Receiver {
      translation 1.75 0 0
      name "rec18"
      channel 19
    }
    Receiver {
      translation 1.75 0 0
      name "rec19"
      channel 20
    }
    Receiver {
      translation 1.75 0 0
      name "rec20"
      channel 21
    }
    Receiver {
      translation 1.75 0 0
      name "rec21"
      channel 22
    }
    Receiver {
      translation 1.75 0 0
      name "rec22"
      channel 23
    }
    Receiver {
      translation 1.75 0 0
      name "rec23"
      channel 24
    }
    Receiver {
      translation 1.75 0 0
      name "rec24"
      channel 25
    }
    Emitter {
      name "trans"
      range 1
      maxRange 1
      channel 4
    }
    Compass {
      name "com"
      yAxis FALSE
    }
    LightSensor {
      translation -0.02 0.04 0.02
      rotation 0 1 0 -2.35619
      children [
        DEF ls Shape {
          appearance Appearance {
            material Material {
              diffuseColor 1 1 0
            }
          }
          geometry Box {
            size 0.01 0.04 0.01
          }
        }
      ]
      name "ls1"
      boundingObject USE ls
      physics Physics {
      }
      occlusion TRUE
    }
    LightSensor {
      translation -0.02 0.04 -0.02
      rotation 0 1 0 -3.92699
      children [
        DEF ls Shape {
          appearance Appearance {
            material Material {
              diffuseColor 1 1 0
            }
          }
          geometry Box {
            size 0.01 0.04 0.01
          }
        }
      ]
      name "ls2"
      boundingObject USE ls
      physics Physics {
      }
      occlusion TRUE
    }
    LightSensor {
      translation 0.02 0.04 -0.02
      rotation 0 1 0 0.785398
      children [
        DEF ls Shape {
          appearance Appearance {
            material Material {
              diffuseColor 1 1 0
            }
          }
          geometry Box {
            size 0.01 0.04 0.01
          }
        }
      ]
      name "ls3"
      boundingObject USE ls
      physics Physics {
      }
      occlusion TRUE
    }
    LightSensor {
      translation 0.02 0.04 0.02
      rotation 0 1 0 -0.785398
      children [
        DEF ls Shape {
          appearance Appearance {
            material Material {
              diffuseColor 1 1 0
            }
          }
          geometry Box {
            size 0.01 0.04 0.01
          }
        }
      ]
      name "ls4"
      boundingObject USE ls
      physics Physics {
      }
      occlusion TRUE
    }
    DistanceSensor {
      translation 0 0 0.1
      rotation 0 1 0 -1.5708
      children [
        DEF DS Shape {
          appearance Appearance {
            material Material {
            }
          }
          geometry Box {
            size 0.01 0.01 0.01
          }
        }
      ]
      name "ds"
      boundingObject USE DS
      physics Physics {
      }
      lookupTable [
        0 0 0
        0.2 400 0
        0.5 1000 0
      ]
    }
    HingeJoint {
      jointParameters HingeJointParameters {
        anchor -0.06 0 -0.05
      }
      device [
        DEF wheel4 RotationalMotor {
          name "wheel4"
          acceleration 1
        }
      ]
      endPoint DEF WHEEL4 Solid {
        translation -0.05999991814307717 -9.632061444724494e-06 -0.05000362374001422
        rotation 0.03312248218235521 -0.03304576865397035 0.9989048394857981 1.571866762233069
        children [
          DEF WHEEL Shape {
            appearance Appearance {
              material Material {
                diffuseColor 0 0 1
              }
            }
            geometry Cylinder {
              height 0.02
              radius 0.04
            }
          }
        ]
        name "wheel4"
        boundingObject USE WHEEL
        physics DEF WHEEL_PH Physics {
        }
      }
    }
    HingeJoint {
      jointParameters HingeJointParameters {
        anchor 0.06 0 -0.05
      }
      device [
        DEF wheel3 RotationalMotor {
          name "wheel3"
          acceleration 1
        }
      ]
      endPoint DEF WHEEL3 Solid {
        translation 0.060000176302764274 -1.3570422243021472e-05 -0.04999976121740486
        rotation 0.033052858076168264 -0.03297527418051867 0.9989094753108093 1.5718690848001053
        children [
          DEF WHEEL Shape {
            appearance Appearance {
              material Material {
                diffuseColor 0 0 1
              }
            }
            geometry Cylinder {
              height 0.02
              radius 0.04
            }
          }
        ]
        name "wheel3"
        boundingObject USE WHEEL
        physics USE WHEEL_PH
      }
    }
    HingeJoint {
      jointParameters HingeJointParameters {
        anchor -0.06 0 0.05
      }
      device [
        DEF wheel2 RotationalMotor {
          name "wheel2"
          acceleration 1
        }
      ]
      endPoint DEF WHEEL2 Solid {
        translation -0.060002157958187 -8.7540512070535e-06 0.049996310781291034
        rotation 0.033122390039492314 -0.03304586831487273 0.9989048392441533 1.5718664036508943
        children [
          DEF WHEEL Shape {
            appearance Appearance {
              material Material {
                diffuseColor 0 0 1
              }
            }
            geometry Cylinder {
              height 0.02
              radius 0.04
            }
          }
        ]
        name "wheel2"
        boundingObject USE WHEEL
        physics DEF WHEEL_PH Physics {
        }
      }
    }
    DEF BODY Shape {
      appearance Appearance {
        material Material {
          diffuseColor 1 0 0
        }
      }
      geometry Box {
        size 0.1 0.05 0.2
      }
    }
    HingeJoint {
      jointParameters HingeJointParameters {
        anchor 0.06 0 0.05
      }
      device [
        DEF wheel1 RotationalMotor {
          name "wheel1"
        }
      ]
      endPoint DEF WHEEL1 Solid {
        translation 0.06000190297626937 6.2227360664119e-06 0.049995882054905696
        rotation -0.04651496824615402 0.046637305478202655 -0.9978283015964179 4.710224110905362
        children [
          DEF WHEEL Shape {
            appearance Appearance {
              material Material {
                diffuseColor 0 0 1
              }
            }
            geometry Cylinder {
              height 0.02
              radius 0.04
            }
          }
        ]
        name "wheel1"
        boundingObject USE WHEEL
        physics USE WHEEL_PH
      }
    }
  ]
  name "RL(2)"
  boundingObject USE BODY
  physics Physics {
  }
  controller "RobotLightP_4_robota"
}
DEF RobotLightC4 Robot {
  translation 0.16 0.04 -2.47
  children [
    Receiver {
      name "rec1"
      channel 1
    }
    Receiver {
      name "rec2"
      channel 2
    }
    Receiver {
      name "rec3"
      channel 3
    }
    Receiver {
      name "rec5"
      channel 5
    }
    Receiver {
      name "rec6"
      channel 6
    }
    Receiver {
      name "rec7"
      channel 7
    }
    Receiver {
      name "rec8"
      channel 8
    }
    Receiver {
      name "rec9"
      channel 9
    }
    Receiver {
      name "rec4"
      channel 10
    }
    Receiver {
      name "rec10"
      channel 11
    }
    Receiver {
      name "rec11"
      channel 12
    }
    Receiver {
      name "rec12"
      channel 13
    }
    Receiver {
      name "rec13"
      channel 14
    }
    Receiver {
      name "rec14"
      channel 15
    }
    Receiver {
      name "rec15"
      channel 14
    }
    Receiver {
      translation 1.75 0 0
      name "rec16"
      channel 17
    }
    Receiver {
      translation 1.75 0 0
      name "rec17"
      channel 18
    }
    Receiver {
      translation 1.75 0 0
      name "rec18"
      channel 19
    }
    Receiver {
      translation 1.75 0 0
      name "rec19"
      channel 20
    }
    Receiver {
      translation 1.75 0 0
      name "rec20"
      channel 21
    }
    Receiver {
      translation 1.75 0 0
      name "rec21"
      channel 22
    }
    Receiver {
      translation 1.75 0 0
      name "rec22"
      channel 23
    }
    Receiver {
      translation 1.75 0 0
      name "rec23"
      channel 24
    }
    Receiver {
      translation 1.75 0 0
      name "rec24"
      channel 25
    }
    Emitter {
      name "trans"
      range 1
      maxRange 1
      channel 4
    }
    Compass {
      name "com"
      yAxis FALSE
    }
    LightSensor {
      translation -0.02 0.04 0.02
      rotation 0 1 0 -2.35619
      children [
        DEF ls Shape {
          appearance Appearance {
            material Material {
              diffuseColor 1 1 0
            }
          }
          geometry Box {
            size 0.01 0.04 0.01
          }
        }
      ]
      name "ls1"
      boundingObject USE ls
      physics Physics {
      }
      occlusion TRUE
    }
    LightSensor {
      translation -0.02 0.04 -0.02
      rotation 0 1 0 -3.92699
      children [
        DEF ls Shape {
          appearance Appearance {
            material Material {
              diffuseColor 1 1 0
            }
          }
          geometry Box {
            size 0.01 0.04 0.01
          }
        }
      ]
      name "ls2"
      boundingObject USE ls
      physics Physics {
      }
      occlusion TRUE
    }
    LightSensor {
      translation 0.02 0.04 -0.02
      rotation 0 1 0 0.785398
      children [
        DEF ls Shape {
          appearance Appearance {
            material Material {
              diffuseColor 1 1 0
            }
          }
          geometry Box {
            size 0.01 0.04 0.01
          }
        }
      ]
      name "ls3"
      boundingObject USE ls
      physics Physics {
      }
      occlusion TRUE
    }
    LightSensor {
      translation 0.02 0.04 0.02
      rotation 0 1 0 -0.785398
      children [
        DEF ls Shape {
          appearance Appearance {
            material Material {
              diffuseColor 1 1 0
            }
          }
          geometry Box {
            size 0.01 0.04 0.01
          }
        }
      ]
      name "ls4"
      boundingObject USE ls
      physics Physics {
      }
      occlusion TRUE
    }
    DistanceSensor {
      translation 0 0 0.1
      rotation 0 1 0 -1.5708
      children [
        DEF DS Shape {
          appearance Appearance {
            material Material {
            }
          }
          geometry Box {
            size 0.01 0.01 0.01
          }
        }
      ]
      name "ds"
      boundingObject USE DS
      physics Physics {
      }
      lookupTable [
        0 0 0
        0.2 400 0
        0.5 1000 0
      ]
    }
    HingeJoint {
      jointParameters HingeJointParameters {
        anchor -0.06 0 -0.05
      }
      device [
        DEF wheel4 RotationalMotor {
          name "wheel4"
          acceleration 1
        }
      ]
      endPoint DEF WHEEL4 Solid {
        translation -0.05999991814307717 -9.632061444724494e-06 -0.05000362374001422
        rotation 0.03312248218235521 -0.03304576865397035 0.9989048394857981 1.571866762233069
        children [
          DEF WHEEL Shape {
            appearance Appearance {
              material Material {
                diffuseColor 0 0 1
              }
            }
            geometry Cylinder {
              height 0.02
              radius 0.04
            }
          }
        ]
        name "wheel4"
        boundingObject USE WHEEL
        physics DEF WHEEL_PH Physics {
        }
      }
    }
    HingeJoint {
      jointParameters HingeJointParameters {
        anchor 0.06 0 -0.05
      }
      device [
        DEF wheel3 RotationalMotor {
          name "wheel3"
          acceleration 1
        }
      ]
      endPoint DEF WHEEL3 Solid {
        translation 0.060000176302764274 -1.3570422243021472e-05 -0.04999976121740486
        rotation 0.033052858076168264 -0.03297527418051867 0.9989094753108093 1.5718690848001053
        children [
          DEF WHEEL Shape {
            appearance Appearance {
              material Material {
                diffuseColor 0 0 1
              }
            }
            geometry Cylinder {
              height 0.02
              radius 0.04
            }
          }
        ]
        name "wheel3"
        boundingObject USE WHEEL
        physics USE WHEEL_PH
      }
    }
    HingeJoint {
      jointParameters HingeJointParameters {
        anchor -0.06 0 0.05
      }
      device [
        DEF wheel2 RotationalMotor {
          name "wheel2"
          acceleration 1
        }
      ]
      endPoint DEF WHEEL2 Solid {
        translation -0.060002157958187 -8.7540512070535e-06 0.049996310781291034
        rotation 0.033122390039492314 -0.03304586831487273 0.9989048392441533 1.5718664036508943
        children [
          DEF WHEEL Shape {
            appearance Appearance {
              material Material {
                diffuseColor 0 0 1
              }
            }
            geometry Cylinder {
              height 0.02
              radius 0.04
            }
          }
        ]
        name "wheel2"
        boundingObject USE WHEEL
        physics DEF WHEEL_PH Physics {
        }
      }
    }
    DEF BODY Shape {
      appearance Appearance {
        material Material {
          diffuseColor 1 0 0
        }
      }
      geometry Box {
        size 0.1 0.05 0.2
      }
    }
    HingeJoint {
      jointParameters HingeJointParameters {
        anchor 0.06 0 0.05
      }
      device [
        DEF wheel1 RotationalMotor {
          name "wheel1"
        }
      ]
      endPoint DEF WHEEL1 Solid {
        translation 0.06000190297626937 6.2227360664119e-06 0.049995882054905696
        rotation -0.04651496824615402 0.046637305478202655 -0.9978283015964179 4.710224110905362
        children [
          DEF WHEEL Shape {
            appearance Appearance {
              material Material {
                diffuseColor 0 0 1
              }
            }
            geometry Cylinder {
              height 0.02
              radius 0.04
            }
          }
        ]
        name "wheel1"
        boundingObject USE WHEEL
        physics USE WHEEL_PH
      }
    }
  ]
  name "RL(3)"
  boundingObject USE BODY
  physics Physics {
  }
  controller "RobotLightP_4_robota"
}
DEF RobotLightC5 Robot {
  translation -0.38 0.04 -2.52
  children [
    Receiver {
      name "rec1"
      channel 1
    }
    Receiver {
      name "rec2"
      channel 2
    }
    Receiver {
      name "rec3"
      channel 3
    }
    Receiver {
      name "rec4"
      channel 4
    }
    Receiver {
      name "rec6"
      channel 6
    }
    Receiver {
      name "rec7"
      channel 7
    }
    Receiver {
      name "rec8"
      channel 8
    }
    Receiver {
      name "rec9"
      channel 9
    }
    Receiver {
      name "rec5"
      channel 10
    }
    Receiver {
      name "rec10"
      channel 11
    }
    Receiver {
      name "rec11"
      channel 12
    }
    Receiver {
      name "rec12"
      channel 13
    }
    Receiver {
      name "rec13"
      channel 14
    }
    Receiver {
      name "rec14"
      channel 15
    }
    Receiver {
      name "rec15"
      channel 14
    }
    Receiver {
      translation 1.75 0 0
      name "rec16"
      channel 17
    }
    Receiver {
      translation 1.75 0 0
      name "rec17"
      channel 18
    }
    Receiver {
      translation 1.75 0 0
      name "rec18"
      channel 19
    }
    Receiver {
      translation 1.75 0 0
      name "rec19"
      channel 20
    }
    Receiver {
      translation 1.75 0 0
      name "rec20"
      channel 21
    }
    Receiver {
      translation 1.75 0 0
      name "rec21"
      channel 22
    }
    Receiver {
      translation 1.75 0 0
      name "rec22"
      channel 23
    }
    Receiver {
      translation 1.75 0 0
      name "rec23"
      channel 24
    }
    Receiver {
      translation 1.75 0 0
      name "rec24"
      channel 25
    }
    Emitter {
      name "trans"
      range 1
      maxRange 1
      channel 5
    }
    Compass {
      name "com"
      yAxis FALSE
    }
    LightSensor {
      translation -0.02 0.04 0.02
      rotation 0 1 0 -2.35619
      children [
        DEF ls Shape {
          appearance Appearance {
            material Material {
              diffuseColor 1 1 0
            }
          }
          geometry Box {
            size 0.01 0.04 0.01
          }
        }
      ]
      name "ls1"
      boundingObject USE ls
      physics Physics {
      }
      occlusion TRUE
    }
    LightSensor {
      translation -0.02 0.04 -0.02
      rotation 0 1 0 -3.92699
      children [
        DEF ls Shape {
          appearance Appearance {
            material Material {
              diffuseColor 1 1 0
            }
          }
          geometry Box {
            size 0.01 0.04 0.01
          }
        }
      ]
      name "ls2"
      boundingObject USE ls
      physics Physics {
      }
      occlusion TRUE
    }
    LightSensor {
      translation 0.02 0.04 -0.02
      rotation 0 1 0 0.785398
      children [
        DEF ls Shape {
          appearance Appearance {
            material Material {
              diffuseColor 1 1 0
            }
          }
          geometry Box {
            size 0.01 0.04 0.01
          }
        }
      ]
      name "ls3"
      boundingObject USE ls
      physics Physics {
      }
      occlusion TRUE
    }
    LightSensor {
      translation 0.02 0.04 0.02
      rotation 0 1 0 -0.785398
      children [
        DEF ls Shape {
          appearance Appearance {
            material Material {
              diffuseColor 1 1 0
            }
          }
          geometry Box {
            size 0.01 0.04 0.01
          }
        }
      ]
      name "ls4"
      boundingObject USE ls
      physics Physics {
      }
      occlusion TRUE
    }
    DistanceSensor {
      translation 0 0 0.1
      rotation 0 1 0 -1.5708
      children [
        DEF DS Shape {
          appearance Appearance {
            material Material {
            }
          }
          geometry Box {
            size 0.01 0.01 0.01
          }
        }
      ]
      name "ds"
      boundingObject USE DS
      physics Physics {
      }
      lookupTable [
        0 0 0
        0.2 400 0
        0.5 1000 0
      ]
    }
    HingeJoint {
      jointParameters HingeJointParameters {
        anchor -0.06 0 -0.05
      }
      device [
        DEF wheel4 RotationalMotor {
          name "wheel4"
          acceleration 1
        }
      ]
      endPoint DEF WHEEL4 Solid {
        translation -0.05999991814307717 -9.632061444724494e-06 -0.05000362374001422
        rotation 0.03312248218235521 -0.03304576865397035 0.9989048394857981 1.571866762233069
        children [
          DEF WHEEL Shape {
            appearance Appearance {
              material Material {
                diffuseColor 0 0 1
              }
            }
            geometry Cylinder {
              height 0.02
              radius 0.04
            }
          }
        ]
        name "wheel4"
        boundingObject USE WHEEL
        physics DEF WHEEL_PH Physics {
        }
      }
    }
    HingeJoint {
      jointParameters HingeJointParameters {
        anchor 0.06 0 -0.05
      }
      device [
        DEF wheel3 RotationalMotor {
          name "wheel3"
          acceleration 1
        }
      ]
      endPoint DEF WHEEL3 Solid {
        translation 0.060000176302764274 -1.3570422243021472e-05 -0.04999976121740486
        rotation 0.033052858076168264 -0.03297527418051867 0.9989094753108093 1.5718690848001053
        children [
          DEF WHEEL Shape {
            appearance Appearance {
              material Material {
                diffuseColor 0 0 1
              }
            }
            geometry Cylinder {
              height 0.02
              radius 0.04
            }
          }
        ]
        name "wheel3"
        boundingObject USE WHEEL
        physics USE WHEEL_PH
      }
    }
    HingeJoint {
      jointParameters HingeJointParameters {
        anchor -0.06 0 0.05
      }
      device [
        DEF wheel2 RotationalMotor {
          name "wheel2"
          acceleration 1
        }
      ]
      endPoint DEF WHEEL2 Solid {
        translation -0.060002157958187 -8.7540512070535e-06 0.049996310781291034
        rotation 0.033122390039492314 -0.03304586831487273 0.9989048392441533 1.5718664036508943
        children [
          DEF WHEEL Shape {
            appearance Appearance {
              material Material {
                diffuseColor 0 0 1
              }
            }
            geometry Cylinder {
              height 0.02
              radius 0.04
            }
          }
        ]
        name "wheel2"
        boundingObject USE WHEEL
        physics DEF WHEEL_PH Physics {
        }
      }
    }
    DEF BODY Shape {
      appearance Appearance {
        material Material {
          diffuseColor 1 0 0
        }
      }
      geometry Box {
        size 0.1 0.05 0.2
      }
    }
    HingeJoint {
      jointParameters HingeJointParameters {
        anchor 0.06 0 0.05
      }
      device [
        DEF wheel1 RotationalMotor {
          name "wheel1"
        }
      ]
      endPoint DEF WHEEL1 Solid {
        translation 0.06000190297626937 6.2227360664119e-06 0.049995882054905696
        rotation -0.04651496824615402 0.046637305478202655 -0.9978283015964179 4.710224110905362
        children [
          DEF WHEEL Shape {
            appearance Appearance {
              material Material {
                diffuseColor 0 0 1
              }
            }
            geometry Cylinder {
              height 0.02
              radius 0.04
            }
          }
        ]
        name "wheel1"
        boundingObject USE WHEEL
        physics USE WHEEL_PH
      }
    }
  ]
  name "RL(4)"
  boundingObject USE BODY
  physics Physics {
  }
  controller "RobotLightP_4_robota"
}
DEF RobotLightC6 Robot {
  translation -2.34 0.04 -2.39
  children [
    Receiver {
      name "rec1"
      channel 1
    }
    Receiver {
      name "rec2"
      channel 2
    }
    Receiver {
      name "rec3"
      channel 3
    }
    Receiver {
      name "rec4"
      channel 4
    }
    Receiver {
      name "rec5"
      channel 5
    }
    Receiver {
      name "rec7"
      channel 7
    }
    Receiver {
      name "rec8"
      channel 8
    }
    Receiver {
      name "rec9"
      channel 9
    }
    Receiver {
      name "rec6"
      channel 10
    }
    Receiver {
      name "rec10"
      channel 11
    }
    Receiver {
      name "rec11"
      channel 12
    }
    Receiver {
      name "rec12"
      channel 13
    }
    Receiver {
      name "rec13"
      channel 14
    }
    Receiver {
      name "rec14"
      channel 15
    }
    Receiver {
      name "rec15"
      channel 14
    }
    Receiver {
      translation 1.75 0 0
      name "rec16"
      channel 17
    }
    Receiver {
      translation 1.75 0 0
      name "rec17"
      channel 18
    }
    Receiver {
      translation 1.75 0 0
      name "rec18"
      channel 19
    }
    Receiver {
      translation 1.75 0 0
      name "rec19"
      channel 20
    }
    Receiver {
      translation 1.75 0 0
      name "rec20"
      channel 21
    }
    Receiver {
      translation 1.75 0 0
      name "rec21"
      channel 22
    }
    Receiver {
      translation 1.75 0 0
      name "rec22"
      channel 23
    }
    Receiver {
      translation 1.75 0 0
      name "rec23"
      channel 24
    }
    Receiver {
      translation 1.75 0 0
      name "rec24"
      channel 25
    }
    Emitter {
      name "trans"
      range 1
      maxRange 1
      channel 6
    }
    Compass {
      name "com"
      yAxis FALSE
    }
    LightSensor {
      translation -0.02 0.04 0.02
      rotation 0 1 0 -2.35619
      children [
        DEF ls Shape {
          appearance Appearance {
            material Material {
              diffuseColor 1 1 0
            }
          }
          geometry Box {
            size 0.01 0.04 0.01
          }
        }
      ]
      name "ls1"
      boundingObject USE ls
      physics Physics {
      }
      occlusion TRUE
    }
    LightSensor {
      translation -0.02 0.04 -0.02
      rotation 0 1 0 -3.92699
      children [
        DEF ls Shape {
          appearance Appearance {
            material Material {
              diffuseColor 1 1 0
            }
          }
          geometry Box {
            size 0.01 0.04 0.01
          }
        }
      ]
      name "ls2"
      boundingObject USE ls
      physics Physics {
      }
      occlusion TRUE
    }
    LightSensor {
      translation 0.02 0.04 -0.02
      rotation 0 1 0 0.785398
      children [
        DEF ls Shape {
          appearance Appearance {
            material Material {
              diffuseColor 1 1 0
            }
          }
          geometry Box {
            size 0.01 0.04 0.01
          }
        }
      ]
      name "ls3"
      boundingObject USE ls
      physics Physics {
      }
      occlusion TRUE
    }
    LightSensor {
      translation 0.02 0.04 0.02
      rotation 0 1 0 -0.785398
      children [
        DEF ls Shape {
          appearance Appearance {
            material Material {
              diffuseColor 1 1 0
            }
          }
          geometry Box {
            size 0.01 0.04 0.01
          }
        }
      ]
      name "ls4"
      boundingObject USE ls
      physics Physics {
      }
      occlusion TRUE
    }
    DistanceSensor {
      translation 0 0 0.1
      rotation 0 1 0 -1.5708
      children [
        DEF DS Shape {
          appearance Appearance {
            material Material {
            }
          }
          geometry Box {
            size 0.01 0.01 0.01
          }
        }
      ]
      name "ds"
      boundingObject USE DS
      physics Physics {
      }
      lookupTable [
        0 0 0
        0.2 400 0
        0.5 1000 0
      ]
    }
    HingeJoint {
      jointParameters HingeJointParameters {
        anchor -0.06 0 -0.05
      }
      device [
        DEF wheel4 RotationalMotor {
          name "wheel4"
          acceleration 1
        }
      ]
      endPoint DEF WHEEL4 Solid {
        translation -0.05999991814307717 -9.632061444724494e-06 -0.05000362374001422
        rotation 0.03312248218235521 -0.03304576865397035 0.9989048394857981 1.571866762233069
        children [
          DEF WHEEL Shape {
            appearance Appearance {
              material Material {
                diffuseColor 0 0 1
              }
            }
            geometry Cylinder {
              height 0.02
              radius 0.04
            }
          }
        ]
        name "wheel4"
        boundingObject USE WHEEL
        physics DEF WHEEL_PH Physics {
        }
      }
    }
    HingeJoint {
      jointParameters HingeJointParameters {
        anchor 0.06 0 -0.05
      }
      device [
        DEF wheel3 RotationalMotor {
          name "wheel3"
          acceleration 1
        }
      ]
      endPoint DEF WHEEL3 Solid {
        translation 0.060000176302764274 -1.3570422243021472e-05 -0.04999976121740486
        rotation 0.033052858076168264 -0.03297527418051867 0.9989094753108093 1.5718690848001053
        children [
          DEF WHEEL Shape {
            appearance Appearance {
              material Material {
                diffuseColor 0 0 1
              }
            }
            geometry Cylinder {
              height 0.02
              radius 0.04
            }
          }
        ]
        name "wheel3"
        boundingObject USE WHEEL
        physics USE WHEEL_PH
      }
    }
    HingeJoint {
      jointParameters HingeJointParameters {
        anchor -0.06 0 0.05
      }
      device [
        DEF wheel2 RotationalMotor {
          name "wheel2"
          acceleration 1
        }
      ]
      endPoint DEF WHEEL2 Solid {
        translation -0.060002157958187 -8.7540512070535e-06 0.049996310781291034
        rotation 0.033122390039492314 -0.03304586831487273 0.9989048392441533 1.5718664036508943
        children [
          DEF WHEEL Shape {
            appearance Appearance {
              material Material {
                diffuseColor 0 0 1
              }
            }
            geometry Cylinder {
              height 0.02
              radius 0.04
            }
          }
        ]
        name "wheel2"
        boundingObject USE WHEEL
        physics DEF WHEEL_PH Physics {
        }
      }
    }
    DEF BODY Shape {
      appearance Appearance {
        material Material {
          diffuseColor 1 0 0
        }
      }
      geometry Box {
        size 0.1 0.05 0.2
      }
    }
    HingeJoint {
      jointParameters HingeJointParameters {
        anchor 0.06 0 0.05
      }
      device [
        DEF wheel1 RotationalMotor {
          name "wheel1"
        }
      ]
      endPoint DEF WHEEL1 Solid {
        translation 0.06000190297626937 6.2227360664119e-06 0.049995882054905696
        rotation -0.04651496824615402 0.046637305478202655 -0.9978283015964179 4.710224110905362
        children [
          DEF WHEEL Shape {
            appearance Appearance {
              material Material {
                diffuseColor 0 0 1
              }
            }
            geometry Cylinder {
              height 0.02
              radius 0.04
            }
          }
        ]
        name "wheel1"
        boundingObject USE WHEEL
        physics USE WHEEL_PH
      }
    }
  ]
  name "RL(5)"
  boundingObject USE BODY
  physics Physics {
  }
  controller "RobotLightP_4_robota"
}
DEF RobotLightC7 Robot {
  translation 0.63 0.04 -2.48
  children [
    Receiver {
      name "rec1"
      channel 1
    }
    Receiver {
      name "rec2"
      channel 2
    }
    Receiver {
      name "rec3"
      channel 3
    }
    Receiver {
      name "rec4"
      channel 4
    }
    Receiver {
      name "rec5"
      channel 5
    }
    Receiver {
      name "rec6"
      channel 6
    }
    Receiver {
      name "rec8"
      channel 8
    }
    Receiver {
      name "rec9"
      channel 9
    }
    Receiver {
      name "rec7"
      channel 10
    }
    Receiver {
      name "rec10"
      channel 11
    }
    Receiver {
      name "rec11"
      channel 12
    }
    Receiver {
      name "rec12"
      channel 13
    }
    Receiver {
      name "rec13"
      channel 14
    }
    Receiver {
      name "rec14"
      channel 15
    }
    Receiver {
      name "rec15"
      channel 14
    }
    Receiver {
      translation 1.75 0 0
      name "rec16"
      channel 17
    }
    Receiver {
      translation 1.75 0 0
      name "rec17"
      channel 18
    }
    Receiver {
      translation 1.75 0 0
      name "rec18"
      channel 19
    }
    Receiver {
      translation 1.75 0 0
      name "rec19"
      channel 20
    }
    Receiver {
      translation 1.75 0 0
      name "rec20"
      channel 21
    }
    Receiver {
      translation 1.75 0 0
      name "rec21"
      channel 22
    }
    Receiver {
      translation 1.75 0 0
      name "rec22"
      channel 23
    }
    Receiver {
      translation 1.75 0 0
      name "rec23"
      channel 24
    }
    Receiver {
      translation 1.75 0 0
      name "rec24"
      channel 25
    }
    Emitter {
      name "trans"
      range 1
      maxRange 1
      channel 7
    }
    Compass {
      name "com"
      yAxis FALSE
    }
    LightSensor {
      translation -0.02 0.04 0.02
      rotation 0 1 0 -2.35619
      children [
        DEF ls Shape {
          appearance Appearance {
            material Material {
              diffuseColor 1 1 0
            }
          }
          geometry Box {
            size 0.01 0.04 0.01
          }
        }
      ]
      name "ls1"
      boundingObject USE ls
      physics Physics {
      }
      occlusion TRUE
    }
    LightSensor {
      translation -0.02 0.04 -0.02
      rotation 0 1 0 -3.92699
      children [
        DEF ls Shape {
          appearance Appearance {
            material Material {
              diffuseColor 1 1 0
            }
          }
          geometry Box {
            size 0.01 0.04 0.01
          }
        }
      ]
      name "ls2"
      boundingObject USE ls
      physics Physics {
      }
      occlusion TRUE
    }
    LightSensor {
      translation 0.02 0.04 -0.02
      rotation 0 1 0 0.785398
      children [
        DEF ls Shape {
          appearance Appearance {
            material Material {
              diffuseColor 1 1 0
            }
          }
          geometry Box {
            size 0.01 0.04 0.01
          }
        }
      ]
      name "ls3"
      boundingObject USE ls
      physics Physics {
      }
      occlusion TRUE
    }
    LightSensor {
      translation 0.02 0.04 0.02
      rotation 0 1 0 -0.785398
      children [
        DEF ls Shape {
          appearance Appearance {
            material Material {
              diffuseColor 1 1 0
            }
          }
          geometry Box {
            size 0.01 0.04 0.01
          }
        }
      ]
      name "ls4"
      boundingObject USE ls
      physics Physics {
      }
      occlusion TRUE
    }
    DistanceSensor {
      translation 0 0 0.1
      rotation 0 1 0 -1.5708
      children [
        DEF DS Shape {
          appearance Appearance {
            material Material {
            }
          }
          geometry Box {
            size 0.01 0.01 0.01
          }
        }
      ]
      name "ds"
      boundingObject USE DS
      physics Physics {
      }
      lookupTable [
        0 0 0
        0.2 400 0
        0.5 1000 0
      ]
    }
    HingeJoint {
      jointParameters HingeJointParameters {
        anchor -0.06 0 -0.05
      }
      device [
        DEF wheel4 RotationalMotor {
          name "wheel4"
          acceleration 1
        }
      ]
      endPoint DEF WHEEL4 Solid {
        translation -0.05999991814307717 -9.632061444724494e-06 -0.05000362374001422
        rotation 0.03312248218235521 -0.03304576865397035 0.9989048394857981 1.571866762233069
        children [
          DEF WHEEL Shape {
            appearance Appearance {
              material Material {
                diffuseColor 0 0 1
              }
            }
            geometry Cylinder {
              height 0.02
              radius 0.04
            }
          }
        ]
        name "wheel4"
        boundingObject USE WHEEL
        physics DEF WHEEL_PH Physics {
        }
      }
    }
    HingeJoint {
      jointParameters HingeJointParameters {
        anchor 0.06 0 -0.05
      }
      device [
        DEF wheel3 RotationalMotor {
          name "wheel3"
          acceleration 1
        }
      ]
      endPoint DEF WHEEL3 Solid {
        translation 0.060000176302764274 -1.3570422243021472e-05 -0.04999976121740486
        rotation 0.033052858076168264 -0.03297527418051867 0.9989094753108093 1.5718690848001053
        children [
          DEF WHEEL Shape {
            appearance Appearance {
              material Material {
                diffuseColor 0 0 1
              }
            }
            geometry Cylinder {
              height 0.02
              radius 0.04
            }
          }
        ]
        name "wheel3"
        boundingObject USE WHEEL
        physics USE WHEEL_PH
      }
    }
    HingeJoint {
      jointParameters HingeJointParameters {
        anchor -0.06 0 0.05
      }
      device [
        DEF wheel2 RotationalMotor {
          name "wheel2"
          acceleration 1
        }
      ]
      endPoint DEF WHEEL2 Solid {
        translation -0.060002157958187 -8.7540512070535e-06 0.049996310781291034
        rotation 0.033122390039492314 -0.03304586831487273 0.9989048392441533 1.5718664036508943
        children [
          DEF WHEEL Shape {
            appearance Appearance {
              material Material {
                diffuseColor 0 0 1
              }
            }
            geometry Cylinder {
              height 0.02
              radius 0.04
            }
          }
        ]
        name "wheel2"
        boundingObject USE WHEEL
        physics DEF WHEEL_PH Physics {
        }
      }
    }
    DEF BODY Shape {
      appearance Appearance {
        material Material {
          diffuseColor 1 0 0
        }
      }
      geometry Box {
        size 0.1 0.05 0.2
      }
    }
    HingeJoint {
      jointParameters HingeJointParameters {
        anchor 0.06 0 0.05
      }
      device [
        DEF wheel1 RotationalMotor {
          name "wheel1"
        }
      ]
      endPoint DEF WHEEL1 Solid {
        translation 0.06000190297626937 6.2227360664119e-06 0.049995882054905696
        rotation -0.04651496824615402 0.046637305478202655 -0.9978283015964179 4.710224110905362
        children [
          DEF WHEEL Shape {
            appearance Appearance {
              material Material {
                diffuseColor 0 0 1
              }
            }
            geometry Cylinder {
              height 0.02
              radius 0.04
            }
          }
        ]
        name "wheel1"
        boundingObject USE WHEEL
        physics USE WHEEL_PH
      }
    }
  ]
  name "RL(6)"
  boundingObject USE BODY
  physics Physics {
  }
  controller "RobotLightP_4_robota"
}
DEF RobotLightC8 Robot {
  translation -1.78 0.04 -2.44
  children [
    Receiver {
      name "rec1"
      channel 1
    }
    Receiver {
      name "rec2"
      channel 2
    }
    Receiver {
      name "rec3"
      channel 3
    }
    Receiver {
      name "rec4"
      channel 4
    }
    Receiver {
      name "rec5"
      channel 5
    }
    Receiver {
      name "rec6"
      channel 6
    }
    Receiver {
      name "rec7"
      channel 7
    }
    Receiver {
      name "rec9"
      channel 9
    }
    Receiver {
      name "rec8"
      channel 10
    }
    Receiver {
      name "rec10"
      channel 11
    }
    Receiver {
      name "rec11"
      channel 12
    }
    Receiver {
      name "rec12"
      channel 13
    }
    Receiver {
      name "rec13"
      channel 14
    }
    Receiver {
      name "rec14"
      channel 15
    }
    Receiver {
      name "rec15"
      channel 14
    }
    Receiver {
      translation 1.75 0 0
      name "rec16"
      channel 17
    }
    Receiver {
      translation 1.75 0 0
      name "rec17"
      channel 18
    }
    Receiver {
      translation 1.75 0 0
      name "rec18"
      channel 19
    }
    Receiver {
      translation 1.75 0 0
      name "rec19"
      channel 20
    }
    Receiver {
      translation 1.75 0 0
      name "rec20"
      channel 21
    }
    Receiver {
      translation 1.75 0 0
      name "rec21"
      channel 22
    }
    Receiver {
      translation 1.75 0 0
      name "rec22"
      channel 23
    }
    Receiver {
      translation 1.75 0 0
      name "rec23"
      channel 24
    }
    Receiver {
      translation 1.75 0 0
      name "rec24"
      channel 25
    }
    Emitter {
      name "trans"
      range 1
      maxRange 1
      channel 8
    }
    Compass {
      name "com"
      yAxis FALSE
    }
    LightSensor {
      translation -0.02 0.04 0.02
      rotation 0 1 0 -2.35619
      children [
        DEF ls Shape {
          appearance Appearance {
            material Material {
              diffuseColor 1 1 0
            }
          }
          geometry Box {
            size 0.01 0.04 0.01
          }
        }
      ]
      name "ls1"
      boundingObject USE ls
      physics Physics {
      }
      occlusion TRUE
    }
    LightSensor {
      translation -0.02 0.04 -0.02
      rotation 0 1 0 -3.92699
      children [
        DEF ls Shape {
          appearance Appearance {
            material Material {
              diffuseColor 1 1 0
            }
          }
          geometry Box {
            size 0.01 0.04 0.01
          }
        }
      ]
      name "ls2"
      boundingObject USE ls
      physics Physics {
      }
      occlusion TRUE
    }
    LightSensor {
      translation 0.02 0.04 -0.02
      rotation 0 1 0 0.785398
      children [
        DEF ls Shape {
          appearance Appearance {
            material Material {
              diffuseColor 1 1 0
            }
          }
          geometry Box {
            size 0.01 0.04 0.01
          }
        }
      ]
      name "ls3"
      boundingObject USE ls
      physics Physics {
      }
      occlusion TRUE
    }
    LightSensor {
      translation 0.02 0.04 0.02
      rotation 0 1 0 -0.785398
      children [
        DEF ls Shape {
          appearance Appearance {
            material Material {
              diffuseColor 1 1 0
            }
          }
          geometry Box {
            size 0.01 0.04 0.01
          }
        }
      ]
      name "ls4"
      boundingObject USE ls
      physics Physics {
      }
      occlusion TRUE
    }
    DistanceSensor {
      translation 0 0 0.1
      rotation 0 1 0 -1.5708
      children [
        DEF DS Shape {
          appearance Appearance {
            material Material {
            }
          }
          geometry Box {
            size 0.01 0.01 0.01
          }
        }
      ]
      name "ds"
      boundingObject USE DS
      physics Physics {
      }
      lookupTable [
        0 0 0
        0.2 400 0
        0.5 1000 0
      ]
    }
    HingeJoint {
      jointParameters HingeJointParameters {
        anchor -0.06 0 -0.05
      }
      device [
        DEF wheel4 RotationalMotor {
          name "wheel4"
          acceleration 1
        }
      ]
      endPoint DEF WHEEL4 Solid {
        translation -0.05999991814307717 -9.632061444724494e-06 -0.05000362374001422
        rotation 0.03312248218235521 -0.03304576865397035 0.9989048394857981 1.571866762233069
        children [
          DEF WHEEL Shape {
            appearance Appearance {
              material Material {
                diffuseColor 0 0 1
              }
            }
            geometry Cylinder {
              height 0.02
              radius 0.04
            }
          }
        ]
        name "wheel4"
        boundingObject USE WHEEL
        physics DEF WHEEL_PH Physics {
        }
      }
    }
    HingeJoint {
      jointParameters HingeJointParameters {
        anchor 0.06 0 -0.05
      }
      device [
        DEF wheel3 RotationalMotor {
          name "wheel3"
          acceleration 1
        }
      ]
      endPoint DEF WHEEL3 Solid {
        translation 0.060000176302764274 -1.3570422243021472e-05 -0.04999976121740486
        rotation 0.033052858076168264 -0.03297527418051867 0.9989094753108093 1.5718690848001053
        children [
          DEF WHEEL Shape {
            appearance Appearance {
              material Material {
                diffuseColor 0 0 1
              }
            }
            geometry Cylinder {
              height 0.02
              radius 0.04
            }
          }
        ]
        name "wheel3"
        boundingObject USE WHEEL
        physics USE WHEEL_PH
      }
    }
    HingeJoint {
      jointParameters HingeJointParameters {
        anchor -0.06 0 0.05
      }
      device [
        DEF wheel2 RotationalMotor {
          name "wheel2"
          acceleration 1
        }
      ]
      endPoint DEF WHEEL2 Solid {
        translation -0.060002157958187 -8.7540512070535e-06 0.049996310781291034
        rotation 0.033122390039492314 -0.03304586831487273 0.9989048392441533 1.5718664036508943
        children [
          DEF WHEEL Shape {
            appearance Appearance {
              material Material {
                diffuseColor 0 0 1
              }
            }
            geometry Cylinder {
              height 0.02
              radius 0.04
            }
          }
        ]
        name "wheel2"
        boundingObject USE WHEEL
        physics DEF WHEEL_PH Physics {
        }
      }
    }
    DEF BODY Shape {
      appearance Appearance {
        material Material {
          diffuseColor 1 0 0
        }
      }
      geometry Box {
        size 0.1 0.05 0.2
      }
    }
    HingeJoint {
      jointParameters HingeJointParameters {
        anchor 0.06 0 0.05
      }
      device [
        DEF wheel1 RotationalMotor {
          name "wheel1"
        }
      ]
      endPoint DEF WHEEL1 Solid {
        translation 0.06000190297626937 6.2227360664119e-06 0.049995882054905696
        rotation -0.04651496824615402 0.046637305478202655 -0.9978283015964179 4.710224110905362
        children [
          DEF WHEEL Shape {
            appearance Appearance {
              material Material {
                diffuseColor 0 0 1
              }
            }
            geometry Cylinder {
              height 0.02
              radius 0.04
            }
          }
        ]
        name "wheel1"
        boundingObject USE WHEEL
        physics USE WHEEL_PH
      }
    }
  ]
  name "RL(7)"
  boundingObject USE BODY
  physics Physics {
  }
  controller "RobotLightP_4_robota"
}
DEF RobotLightC9 Robot {
  translation 1.63 0.04 -2.4
  children [
    Receiver {
      name "rec1"
      channel 1
    }
    Receiver {
      name "rec2"
      channel 2
    }
    Receiver {
      name "rec3"
      channel 3
    }
    Receiver {
      name "rec4"
      channel 4
    }
    Receiver {
      name "rec5"
      channel 5
    }
    Receiver {
      name "rec6"
      channel 6
    }
    Receiver {
      name "rec7"
      channel 7
    }
    Receiver {
      name "rec8"
      channel 8
    }
    Receiver {
      name "rec9"
      channel 10
    }
    Receiver {
      name "rec10"
      channel 11
    }
    Receiver {
      name "rec11"
      channel 12
    }
    Receiver {
      name "rec12"
      channel 13
    }
    Receiver {
      name "rec13"
      channel 14
    }
    Receiver {
      name "rec14"
      channel 15
    }
    Receiver {
      name "rec15"
      channel 14
    }
    Receiver {
      translation 1.75 0 0
      name "rec16"
      channel 17
    }
    Receiver {
      translation 1.75 0 0
      name "rec17"
      channel 18
    }
    Receiver {
      translation 1.75 0 0
      name "rec18"
      channel 19
    }
    Receiver {
      translation 1.75 0 0
      name "rec19"
      channel 20
    }
    Receiver {
      translation 1.75 0 0
      name "rec20"
      channel 21
    }
    Receiver {
      translation 1.75 0 0
      name "rec21"
      channel 22
    }
    Receiver {
      translation 1.75 0 0
      name "rec22"
      channel 23
    }
    Receiver {
      translation 1.75 0 0
      name "rec23"
      channel 24
    }
    Receiver {
      translation 1.75 0 0
      name "rec24"
      channel 25
    }
    Emitter {
      name "trans"
      range 1
      maxRange 1
      channel 9
    }
    Compass {
      name "com"
      yAxis FALSE
    }
    LightSensor {
      translation -0.02 0.04 0.02
      rotation 0 1 0 -2.35619
      children [
        DEF ls Shape {
          appearance Appearance {
            material Material {
              diffuseColor 1 1 0
            }
          }
          geometry Box {
            size 0.01 0.04 0.01
          }
        }
      ]
      name "ls1"
      boundingObject USE ls
      physics Physics {
      }
      occlusion TRUE
    }
    LightSensor {
      translation -0.02 0.04 -0.02
      rotation 0 1 0 -3.92699
      children [
        DEF ls Shape {
          appearance Appearance {
            material Material {
              diffuseColor 1 1 0
            }
          }
          geometry Box {
            size 0.01 0.04 0.01
          }
        }
      ]
      name "ls2"
      boundingObject USE ls
      physics Physics {
      }
      occlusion TRUE
    }
    LightSensor {
      translation 0.02 0.04 -0.02
      rotation 0 1 0 0.785398
      children [
        DEF ls Shape {
          appearance Appearance {
            material Material {
              diffuseColor 1 1 0
            }
          }
          geometry Box {
            size 0.01 0.04 0.01
          }
        }
      ]
      name "ls3"
      boundingObject USE ls
      physics Physics {
      }
      occlusion TRUE
    }
    LightSensor {
      translation 0.02 0.04 0.02
      rotation 0 1 0 -0.785398
      children [
        DEF ls Shape {
          appearance Appearance {
            material Material {
              diffuseColor 1 1 0
            }
          }
          geometry Box {
            size 0.01 0.04 0.01
          }
        }
      ]
      name "ls4"
      boundingObject USE ls
      physics Physics {
      }
      occlusion TRUE
    }
    DistanceSensor {
      translation 0 0 0.1
      rotation 0 1 0 -1.5708
      children [
        DEF DS Shape {
          appearance Appearance {
            material Material {
            }
          }
          geometry Box {
            size 0.01 0.01 0.01
          }
        }
      ]
      name "ds"
      boundingObject USE DS
      physics Physics {
      }
      lookupTable [
        0 0 0
        0.2 400 0
        0.5 1000 0
      ]
    }
    HingeJoint {
      jointParameters HingeJointParameters {
        anchor -0.06 0 -0.05
      }
      device [
        DEF wheel4 RotationalMotor {
          name "wheel4"
          acceleration 1
        }
      ]
      endPoint DEF WHEEL4 Solid {
        translation -0.05999991814307717 -9.632061444724494e-06 -0.05000362374001422
        rotation 0.03312248218235521 -0.03304576865397035 0.9989048394857981 1.571866762233069
        children [
          DEF WHEEL Shape {
            appearance Appearance {
              material Material {
                diffuseColor 0 0 1
              }
            }
            geometry Cylinder {
              height 0.02
              radius 0.04
            }
          }
        ]
        name "wheel4"
        boundingObject USE WHEEL
        physics DEF WHEEL_PH Physics {
        }
      }
    }
    HingeJoint {
      jointParameters HingeJointParameters {
        anchor 0.06 0 -0.05
      }
      device [
        DEF wheel3 RotationalMotor {
          name "wheel3"
          acceleration 1
        }
      ]
      endPoint DEF WHEEL3 Solid {
        translation 0.060000176302764274 -1.3570422243021472e-05 -0.04999976121740486
        rotation 0.033052858076168264 -0.03297527418051867 0.9989094753108093 1.5718690848001053
        children [
          DEF WHEEL Shape {
            appearance Appearance {
              material Material {
                diffuseColor 0 0 1
              }
            }
            geometry Cylinder {
              height 0.02
              radius 0.04
            }
          }
        ]
        name "wheel3"
        boundingObject USE WHEEL
        physics USE WHEEL_PH
      }
    }
    HingeJoint {
      jointParameters HingeJointParameters {
        anchor -0.06 0 0.05
      }
      device [
        DEF wheel2 RotationalMotor {
          name "wheel2"
          acceleration 1
        }
      ]
      endPoint DEF WHEEL2 Solid {
        translation -0.060002157958187 -8.7540512070535e-06 0.049996310781291034
        rotation 0.033122390039492314 -0.03304586831487273 0.9989048392441533 1.5718664036508943
        children [
          DEF WHEEL Shape {
            appearance Appearance {
              material Material {
                diffuseColor 0 0 1
              }
            }
            geometry Cylinder {
              height 0.02
              radius 0.04
            }
          }
        ]
        name "wheel2"
        boundingObject USE WHEEL
        physics DEF WHEEL_PH Physics {
        }
      }
    }
    DEF BODY Shape {
      appearance Appearance {
        material Material {
          diffuseColor 1 0 0
        }
      }
      geometry Box {
        size 0.1 0.05 0.2
      }
    }
    HingeJoint {
      jointParameters HingeJointParameters {
        anchor 0.06 0 0.05
      }
      device [
        DEF wheel1 RotationalMotor {
          name "wheel1"
        }
      ]
      endPoint DEF WHEEL1 Solid {
        translation 0.06000190297626937 6.2227360664119e-06 0.049995882054905696
        rotation -0.04651496824615402 0.046637305478202655 -0.9978283015964179 4.710224110905362
        children [
          DEF WHEEL Shape {
            appearance Appearance {
              material Material {
                diffuseColor 0 0 1
              }
            }
            geometry Cylinder {
              height 0.02
              radius 0.04
            }
          }
        ]
        name "wheel1"
        boundingObject USE WHEEL
        physics USE WHEEL_PH
      }
    }
  ]
  name "RL(8)"
  boundingObject USE BODY
  physics Physics {
  }
  controller "RobotLightP_4_robota"
}
DEF RobotLightC10 Robot {
  translation 1.1 0.04 -2.47
  children [
    Receiver {
      name "rec1"
      channel 1
    }
    Receiver {
      name "rec2"
      channel 2
    }
    Receiver {
      name "rec3"
      channel 3
    }
    Receiver {
      name "rec4"
      channel 4
    }
    Receiver {
      name "rec5"
      channel 5
    }
    Receiver {
      name "rec6"
      channel 6
    }
    Receiver {
      name "rec7"
      channel 7
    }
    Receiver {
      name "rec8"
      channel 8
    }
    Receiver {
      name "rec9"
      channel 9
    }
    Receiver {
      name "rec10"
      channel 11
    }
    Receiver {
      name "rec11"
      channel 12
    }
    Receiver {
      name "rec12"
      channel 13
    }
    Receiver {
      name "rec13"
      channel 14
    }
    Receiver {
      name "rec14"
      channel 15
    }
    Receiver {
      name "rec15"
      channel 14
    }
    Receiver {
      translation 1.75 0 0
      name "rec16"
      channel 17
    }
    Receiver {
      translation 1.75 0 0
      name "rec17"
      channel 18
    }
    Receiver {
      translation 1.75 0 0
      name "rec18"
      channel 19
    }
    Receiver {
      translation 1.75 0 0
      name "rec19"
      channel 20
    }
    Receiver {
      translation 1.75 0 0
      name "rec20"
      channel 21
    }
    Receiver {
      translation 1.75 0 0
      name "rec21"
      channel 22
    }
    Receiver {
      translation 1.75 0 0
      name "rec22"
      channel 23
    }
    Receiver {
      translation 1.75 0 0
      name "rec23"
      channel 24
    }
    Receiver {
      translation 1.75 0 0
      name "rec24"
      channel 25
    }
    Emitter {
      name "trans"
      range 1
      maxRange 1
      channel 10
    }
    Compass {
      name "com"
      yAxis FALSE
    }
    LightSensor {
      translation -0.02 0.04 0.02
      rotation 0 1 0 -2.35619
      children [
        DEF ls Shape {
          appearance Appearance {
            material Material {
              diffuseColor 1 1 0
            }
          }
          geometry Box {
            size 0.01 0.04 0.01
          }
        }
      ]
      name "ls1"
      boundingObject USE ls
      physics Physics {
      }
      occlusion TRUE
    }
    LightSensor {
      translation -0.02 0.04 -0.02
      rotation 0 1 0 -3.92699
      children [
        DEF ls Shape {
          appearance Appearance {
            material Material {
              diffuseColor 1 1 0
            }
          }
          geometry Box {
            size 0.01 0.04 0.01
          }
        }
      ]
      name "ls2"
      boundingObject USE ls
      physics Physics {
      }
      occlusion TRUE
    }
    LightSensor {
      translation 0.02 0.04 -0.02
      rotation 0 1 0 0.785398
      children [
        DEF ls Shape {
          appearance Appearance {
            material Material {
              diffuseColor 1 1 0
            }
          }
          geometry Box {
            size 0.01 0.04 0.01
          }
        }
      ]
      name "ls3"
      boundingObject USE ls
      physics Physics {
      }
      occlusion TRUE
    }
    LightSensor {
      translation 0.02 0.04 0.02
      rotation 0 1 0 -0.785398
      children [
        DEF ls Shape {
          appearance Appearance {
            material Material {
              diffuseColor 1 1 0
            }
          }
          geometry Box {
            size 0.01 0.04 0.01
          }
        }
      ]
      name "ls4"
      boundingObject USE ls
      physics Physics {
      }
      occlusion TRUE
    }
    DistanceSensor {
      translation 0 0 0.1
      rotation 0 1 0 -1.5708
      children [
        DEF DS Shape {
          appearance Appearance {
            material Material {
            }
          }
          geometry Box {
            size 0.01 0.01 0.01
          }
        }
      ]
      name "ds"
      boundingObject USE DS
      physics Physics {
      }
      lookupTable [
        0 0 0
        0.2 400 0
        0.5 1000 0
      ]
    }
    HingeJoint {
      jointParameters HingeJointParameters {
        anchor -0.06 0 -0.05
      }
      device [
        DEF wheel4 RotationalMotor {
          name "wheel4"
          acceleration 1
        }
      ]
      endPoint DEF WHEEL4 Solid {
        translation -0.05999991814307717 -9.632061444724494e-06 -0.05000362374001422
        rotation 0.03312248218235521 -0.03304576865397035 0.9989048394857981 1.571866762233069
        children [
          DEF WHEEL Shape {
            appearance Appearance {
              material Material {
                diffuseColor 0 0 1
              }
            }
            geometry Cylinder {
              height 0.02
              radius 0.04
            }
          }
        ]
        name "wheel4"
        boundingObject USE WHEEL
        physics DEF WHEEL_PH Physics {
        }
      }
    }
    HingeJoint {
      jointParameters HingeJointParameters {
        anchor 0.06 0 -0.05
      }
      device [
        DEF wheel3 RotationalMotor {
          name "wheel3"
          acceleration 1
        }
      ]
      endPoint DEF WHEEL3 Solid {
        translation 0.060000176302764274 -1.3570422243021472e-05 -0.04999976121740486
        rotation 0.033052858076168264 -0.03297527418051867 0.9989094753108093 1.5718690848001053
        children [
          DEF WHEEL Shape {
            appearance Appearance {
              material Material {
                diffuseColor 0 0 1
              }
            }
            geometry Cylinder {
              height 0.02
              radius 0.04
            }
          }
        ]
        name "wheel3"
        boundingObject USE WHEEL
        physics USE WHEEL_PH
      }
    }
    HingeJoint {
      jointParameters HingeJointParameters {
        anchor -0.06 0 0.05
      }
      device [
        DEF wheel2 RotationalMotor {
          name "wheel2"
          acceleration 1
        }
      ]
      endPoint DEF WHEEL2 Solid {
        translation -0.060002157958187 -8.7540512070535e-06 0.049996310781291034
        rotation 0.033122390039492314 -0.03304586831487273 0.9989048392441533 1.5718664036508943
        children [
          DEF WHEEL Shape {
            appearance Appearance {
              material Material {
                diffuseColor 0 0 1
              }
            }
            geometry Cylinder {
              height 0.02
              radius 0.04
            }
          }
        ]
        name "wheel2"
        boundingObject USE WHEEL
        physics DEF WHEEL_PH Physics {
        }
      }
    }
    DEF BODY Shape {
      appearance Appearance {
        material Material {
          diffuseColor 1 0 0
        }
      }
      geometry Box {
        size 0.1 0.05 0.2
      }
    }
    HingeJoint {
      jointParameters HingeJointParameters {
        anchor 0.06 0 0.05
      }
      device [
        DEF wheel1 RotationalMotor {
          name "wheel1"
        }
      ]
      endPoint DEF WHEEL1 Solid {
        translation 0.06000190297626937 6.2227360664119e-06 0.049995882054905696
        rotation -0.04651496824615402 0.046637305478202655 -0.9978283015964179 4.710224110905362
        children [
          DEF WHEEL Shape {
            appearance Appearance {
              material Material {
                diffuseColor 0 0 1
              }
            }
            geometry Cylinder {
              height 0.02
              radius 0.04
            }
          }
        ]
        name "wheel1"
        boundingObject USE WHEEL
        physics USE WHEEL_PH
      }
    }
  ]
  name "RL(9)"
  boundingObject USE BODY
  physics Physics {
  }
  controller "RobotLightP_4_robota"
}
FloorLight {
  translation 0.1 0 6.03
  pointLightIntensity 0
}
FloorLight {
  translation 5.26285 0 0.31501
  rotation 0 1 0 -0.785395307179586
  name "floor light(1)"
  pointLightIntensity 0
}
SolidRoundedBox {
  translation 0 0 -0.23
}
